{
  "questionText": "Как можно обрабатывать исключения, возникающие внутри асинхронной функции, используя конструкцию async/await в JavaScript?",
  "type": "radio",
  "answers": [
    {
      "text": "Используя `try/catch` конструкцию внутри асинхронной функции",
      "isCorrect": true
    },
    {
      "text": "Оборачивая асинхронную функцию в `Promise.catch()` метод",
      "isCorrect": false
    },
    {
      "text": "Используя `window.onerror` событие для обработки исключений",
      "isCorrect": false
    },
    {
      "text": "Используя `setTimeout` функцию для отложенной обработки исключений",
      "isCorrect": false
    }
  ],
  "descriptionMarkup": "В JavaScript, конструкция `async/await` используется для обработки асинхронных операций, и исключения могут возникать внутри асинхронной функции. Для обработки исключений внутри асинхронной функции, необходимо использовать `try/catch` конструкцию."
}
